Workbook

Sheet All Cards
A1: # | B1: Card Name | C1: Fair Value (USD) - EDIT HERE | D1: Confidence | E1: # Sales | F1: Top 3 Prices | G1: Min | H1: Max | I1: Notes | J1: Player | K1: Set
A2: 161 | B2: 2024-25 O-Pee-Chee Platinum - [Base] - Arctic Freeze #263 - Marquee Rookies - Macklin Celebrini #1/99 | C2: 605 | D2: low | E2: 2 | F2: $605.0 | $824.61 | G2: $605.0 | H2: $824.61 | J2: Macklin Celebrini | K2: 2024-25 O-Pee-Chee Platinum
A3: 134 | B3: 2023-24 O-Pee-Chee Platinum - [Base] - Violet Pixels #201 - Marquee Rookies - Connor Bedard [PSA 10 GEM MT] #260/299 | C3: 479.4 | D3: low | E3: 3 | F3: $479.4 | $358.66 | $488.23 | G3: $358.66 | H3: $488.23 | J3: Connor Bedard | K3: 2023-24 O-Pee-Chee Platinum
A4: 185 | B4: 2024-25 Upper Deck Series 2 - [Base] #451 - Young Guns - Macklin Celebrini [PSA 8 NM‑MT] | C4: 368 | D4: high | E4: 49 | F4: $329.73 | $319.48 | $368.0 | G4: $165.5 | H4: $431.31 | J4: Macklin Celebrini | K4: 2024-25 Upper Deck Series 2
A5: 163 | B5: 2024-25 O-Pee-Chee Platinum - [Base] - Red Prism #263 - Marquee Rookies - Macklin Celebrini #2/199 | C5: 317.45 | D5: high | E5: 1 | F5: $317.45 | G5: $317.45 | H5: $317.45 | J5: Macklin Celebrini | K5: 2024-25 O-Pee-Chee Platinum
A6: 142 | B6: 2024-25 SPx - Excellence Redefined - Red #EX-9 - Connor Bedard, Nathan MacKinnon #9/10 | C6: 313.3 | D6: estimated | E6: 2 | F6: $313.3 | $554.6 | G6: $313.3 | H6: $554.6 | J6: Connor Bedard | K6: 2024-25 SPx
A7: 118 | B7: 2023-24 Upper Deck Allure - Color Flow - Orange Yellow Spectrum #CF-16 - Connor Bedard [PSA 10 GEM MT] #125/199 | C7: 300 | D7: manual | J7: Connor Bedard | K7: 2023-24 Upper Deck Allure
A8: 31 | B8: 2023-24 Upper Deck Series 2 - [Base] #451 - Young Guns - Connor Bedard [PSA 9 MINT] | C8: 273.77 | D8: high | E8: 50 | F8: $396.31 | $268.77 | $273.77 | G8: $243.5 | H8: $396.31 | J8: Connor Bedard | K8: 2023-24 Upper Deck Series 2
A9: 109 | B9: 2023-24 O-Pee-Chee Platinum - [Base] - Red Prism #201 - Marquee Rookies - Connor Bedard [PSA 9 MINT] #70/199 | C9: 263.23 | D9: low | E9: 4 | F9: $170.48 | $300.6 | $263.23 | G9: $170.48 | H9: $300.6 | J9: Connor Bedard | K9: 2023-24 O-Pee-Chee Platinum
A10: 135 | B10: 2023-24 O-Pee-Chee Platinum - [Base] - Pond Hockey Variants #202 - Marquee Rookies - Logan Cooley [PSA 10 GEM MT] | C10: 150 | D10: low | E10: 8 | F10: $50.09 | $169.38 | $209.96 | G10: $50.09 | H10: $209.96 | J10: Logan Cooley | K10: 2023-24 O-Pee-Chee Platinum
A11: 137 | B11: 2023-24 O-Pee-Chee Platinum - [Base] - Emerald Surge #53 - Nick Suzuki [PSA 10 GEM MT] #10/10 | C11: 200 | D11: manual | E11: 0 | G11: $5.0 | H11: $5.0 | J11: Nick Suzuki | K11: 2023-24 O-Pee-Chee Platinum
A12: 189 | B12: 2024-25 SPx - [Base] #166 - Rookie Holograms - Macklin Celebrini [PSA 8 NM‑MT] | C12: 200 | D12: manual | E12: 0 | G12: $5.0 | H12: $5.0 | J12: Macklin Celebrini | K12: 2024-25 SPx
A13: 187 | B13: 2025-26 Upper Deck Series 1 - [Base] - Deluxe #236 - Young Guns - Zayne Parekh #106/250 | C13: 196.18 | D13: high | E13: 9 | F13: $184.56 | $196.18 | $142.88 | G13: $65.87 | H13: $196.18 | J13: Zayne Parekh | K13: 2025-26 Upper Deck Series 1
A14: 181 | B14: 2025-26 Upper Deck Series 1 - Bootlegs #BL-18 - Artyom Levshunov | C14: 187.91 | D14: high | E14: 1 | F14: $187.91 | G14: $187.91 | H14: $187.91 | J14: Artyom Levshunov | K14: 2025-26 Upper Deck Series 1
A15: 133 | B15: 2023-24 O-Pee-Chee Platinum - [Base] - Red Prism #293 - Marquee Rookies - Leo Carlsson [PSA 10 GEM MT] #53/199 | C15: 162.96 | D15: low | E15: 5 | F15: $172.99 | $162.96 | $160.13 | G15: $160.13 | H15: $198.21 | J15: Leo Carlsson | K15: 2023-24 O-Pee-Chee Platinum
A16: 154 | B16: 2023-24 SPx - Finite Rookies - Silver Spectrum #F-3 - Matthew Knies #24/49 | C16: 20 | D16: low | E16: 3 | F16: $147.96 | $110.25 | $95.97 | G16: $95.97 | H16: $147.96 | J16: Matthew Knies | K16: 2023-24 SPx
A17: 136 | B17: 2023-24 O-Pee-Chee Platinum - [Base] - Emerald Surge #14 - Jake Sanderson #1/10 | C17: 30 | D17: low | E17: 11 | F17: $75.71 | $136.86 | $87.77 | G17: $25.89 | H17: $182.65 | J17: Jake Sanderson | K17: 2023-24 O-Pee-Chee Platinum
A18: 108 | B18: 2023-24 O-Pee-Chee Platinum - [Base] - NHL Shield Variations #203 - Marquee Rookies - Adam Fantilli [PSA 10 GEM MT] | C18: 124.13 | D18: low | E18: 4 | F18: $124.13 | $65.56 | $65.93 | G18: $40.99 | H18: $124.13 | J18: Adam Fantilli | K18: 2023-24 O-Pee-Chee Platinum
A19: 117 | B19: 2023-24 O-Pee-Chee Platinum - [Base] - Pond Hockey Variants #203 - Marquee Rookies - Adam Fantilli [PSA 10 GEM MT] | C19: 124.13 | D19: low | E19: 4 | F19: $124.13 | $65.56 | $65.93 | G19: $40.99 | H19: $124.13 | J19: Adam Fantilli | K19: 2023-24 O-Pee-Chee Platinum
A20: 174 | B20: 2024 Upper Deck PWHL 1st Edition - UD Portraits - Gold #P-2 - Marie-Philip Poulin [PSA 10 GEM MT] #82/299 | C20: 106.03 | D20: low | E20: 1 | F20: $106.03 | G20: $106.03 | H20: $106.03 | J20: Marie-Philip Poulin | K20: 2024 Upper Deck PWHL 1st Edition
A21: 188 | B21: 2023-24 O-Pee-Chee Platinum - [Base] - Pond Hockey Variants #205 - Marquee Rookies - Matthew Knies | C21: 105.14 | D21: high | E21: 3 | F21: $67.62 | $105.14 | $50.85 | G21: $50.85 | H21: $105.14 | J21: Matthew Knies | K21: 2023-24 O-Pee-Chee Platinum
A22: 91 | B22: 2024 Upper Deck PWHL 1st Edition - [Base] #65 - Young Guns - Marie-Philip Poulin | C22: 100.15 | D22: high | E22: 16 | F22: $86.77 | $100.15 | $115.59 | G22: $54.0 | H22: $188.65 | J22: Marie-Philip Poulin | K22: 2024 Upper Deck PWHL 1st Edition
A23: 178 | B23: 2023-24 O-Pee-Chee Platinum - Photo Driven - Red Pixel #PD-6 - Auston Matthews [PSA 10 GEM MT] #75/85 | C23: 100 | D23: manual | E23: 0 | G23: $5.0 | H23: $5.0 | J23: Auston Matthews | K23: 2023-24 O-Pee-Chee Platinum
A24: 119 | B24: 2023-24 Upper Deck Allure - [Base] - Blue Line Auto Jersey #114 - Rookies - Leo Carlsson #28/35 | C24: 99.59 | D24: low | E24: 1 | F24: $99.59 | G24: $99.59 | H24: $99.59 | J24: Leo Carlsson | K24: 2023-24 Upper Deck Allure
A25: 173 | B25: 2024 Upper Deck PWHL 1st Edition - [Base] - Deluxe #59 - Young Guns - Emma Maltais [PSA 9 MINT] #48/250 | C25: 99 | D25: low | E25: 1 | F25: $99.0 | G25: $99.0 | H25: $99.0 | J25: Emma Maltais | K25: 2024 Upper Deck PWHL 1st Edition
A26: 12 | B26: 2023-24 Upper Deck Series 1 - [Base] - Outburst Silver #44 - Mikko Rantanen | C26: 3 | D26: high | E26: 1 | F26: $98.34 | G26: $98.34 | H26: $98.34 | J26: Mikko Rantanen | K26: 2023-24 Upper Deck Series 1
A27: 72 | B27: 2024-25 Upper Deck Series 2 - [Base] - Deluxe #493 - Young Guns - Brandon Bussi #199/250 | C27: 93.97 | D27: high | E27: 2 | F27: $93.97 | $38.15 | G27: $38.15 | H27: $93.97 | J27: Brandon Bussi | K27: 2024-25 Upper Deck Series 2
A28: 128 | B28: 2024-25 Upper Deck Credentials - Retro Ticket Access Auto Rookies #RTAR-CG - SP - Cutter Gauthier | C28: 82.4 | D28: low | E28: 1 | F28: $82.4 | G28: $82.4 | H28: $82.4 | J28: Cutter Gauthier | K28: 2024-25 Upper Deck Credentials
A29: 132 | B29: 2024 Fleer Scooby Doo - S-S-Scared S-S-Sketches #SKT - Ryan Finley | C29: 71.35 | D29: low | E29: 1 | F29: $71.35 | G29: $71.35 | H29: $71.35 | J29: Ryan Finley | K29: 2024 Fleer Scooby Doo
A30: 114 | B30: 2024-25 Skybox Metal Universe - 2013 Retro #RT-2 - Cutter Gauthier | C30: 62.49 | D30: high | E30: 5 | F30: $62.06 | $62.49 | $62.19 | G30: $28.73 | H30: $62.49 | J30: Cutter Gauthier | K30: 2024-25 Skybox Metal Universe
A31: 143 | B31: 2024-25 Upper Deck Extended Series - [Base] #701 - Young Guns - Will Smith | C31: 59.99 | D31: high | E31: 9 | F31: $43.0 | $62.86 | $59.99 | G31: $40.36 | H31: $62.86 | J31: Will Smith | K31: 2024-25 Upper Deck Extended Series
A32: 182 | B32: 2024-25 O-Pee-Chee Platinum - Rookie Autographs - Red Prism #R-LB - Lian Bichsel #21/30 | C32: 59.49 | D32: low | E32: 1 | F32: $59.49 | G32: $59.49 | H32: $59.49 | J32: Lian Bichsel | K32: 2024-25 O-Pee-Chee Platinum
A33: 175 | B33: 2024 Upper Deck PWHL 1st Edition - [Base] #61 - Young Guns - Taylor Heise [PSA 8 NM‑MT] | C33: 58 | D33: medium | E33: 2 | F33: $58.0 | $74.1 | G33: $58.0 | H33: $74.1 | J33: Taylor Heise | K33: 2024 Upper Deck PWHL 1st Edition
A34: 164 | B34: 2024-25 Upper Deck Series 2 - Day with the Cup #DC10 - Anton Lundell | C34: 57 | D34: high | E34: 2 | F34: $57.0 | $33.95 | G34: $33.95 | H34: $57.0 | J34: Anton Lundell | K34: 2024-25 Upper Deck Series 2
A35: 38 | B35: 2023-24 O-Pee-Chee Platinum - [Base] - Rainbow Color Wheel #201 - Marquee Rookies - Connor Bedard | C35: 55.88 | D35: low | E35: 5 | F35: $55.88 | $82.0 | $96.15 | G35: $55.88 | H35: $96.15 | J35: Connor Bedard | K35: 2023-24 O-Pee-Chee Platinum
... A38: 33 | B38: 2023-24 Upper Deck Series 1 - UD Canvas #C103 - Young Guns - Matthew Knies [PSA 9 MINT] | C38: 52.28 | D38: low | E38: 4 | F38: $54.47 | $52.28 | $204.74 | G38: $52.28 | H38: $204.74 | J38: Matthew Knies | K38: 2023-24 Upper Deck Series 1
A39: 73 | B39: 2023-24 SPx - Signature Fabrics - Spectrum Patch #SF-JT - John Tavares #2/5 | C39: 50 | D39: manual | E39: 0 | G39: $5.0 | H39: $5.0 | J39: John Tavares | K39: 2023-24 SPx
A40: 179 | B40: 2023-24 SPx - [Base] - Purple Parallax #134 - Rookies - Matthew Knies [PSA 9 MINT] #85/149 | C40: 50 | D40: manual | E40: 0 | G40: $5.0 | H40: $5.0 | J40: Matthew Knies | K40: 2023-24 SPx
A41: 183 | B41: 2024-25 Upper Deck Series 2 - Young Guns Renewed #201.3 - Connor McDavid [PSA 9 MINT] | C41: 50 | D41: manual | E41: 0 | G41: $5.0 | H41: $5.0 | J41: Connor McDavid | K41: 2024-25 Upper Deck Series 2
A42: 184 | B42: 2024-25 Upper Deck Series 2 - UD Canvas #C161 - Joseph Woll [PSA 10 GEM MT] | C42: 50 | D42: manual | E42: 0 | G42: $5.0 | H42: $5.0 | J42: Joseph Woll | K42: 2024-25 Upper Deck Series 2
...

Sheet Summary
A1: CARD COLLECTION — PRICE REPORT
A3: OVERVIEW
A4: Total Cards in List | B4: 189
A5: Cards Priced | B5: =COUNTA('All Cards'!$C$2:$C$190)-COUNTIF('All Cards'!$C$2:$C$190,0) -> 189
A6: Manual Entries | B6: =COUNTIF('All Cards'!$D$2:$D$190,"manual") -> 18
A7: Cards Under $5 | B7: =COUNTIFS('All Cards'!$C$2:$C$190,">=0.01",'All Cards'!$C$2:$C$190,"<5") -> 21
A9: VALUATION (edit Fair Value on 'All Cards' sheet to update)
A10: GRAND TOTAL | B10: =SUM('All Cards'!$C$2:$C$190) -> 8091.41
A11: Scraped (eBay) | B11: =SUMIF('All Cards'!$D$2:$D$190,"<>manual",'All Cards'!$C$2:$C$190) -> 6921.41
A12: Manual Comps | B12: =SUMIF('All Cards'!$D$2:$D$190,"manual",'All Cards'!$C$2:$C$190) -> 1170
A14: VALUE BY CONFIDENCE
A15: High (112 cards) | B15: =SUMIF('All Cards'!$D$2:$D$190,"high",'All Cards'!$C$2:$C$190) -> 3487.01
A16: Medium (7 cards) | B16: =SUMIF('All Cards'!$D$2:$D$190,"medium",'All Cards'!$C$2:$C$190) -> 177.8
A17: Low (46 cards) | B17: =SUMIF('All Cards'!$D$2:$D$190,"low",'All Cards'!$C$2:$C$190) -> 2917.06
A18: Estimated (6 cards) | B18: =SUMIF('All Cards'!$D$2:$D$190,"estimated",'All Cards'!$C$2:$C$190) -> 339.54
A19: Manual (18 cards) | B19: =SUMIF('All Cards'!$D$2:$D$190,"manual",'All Cards'!$C$2:$C$190) -> 1170
A21: VALUE TIERS
B22: # Cards | C22: Total USD
A23: $0 – $5 | B23: =COUNTIFS('All Cards'!$C$2:$C$190,">=0",'All Cards'!$C$2:$C$190,"<5") -> 21 | C23: =SUMIFS('All Cards'!$C$2:$C$190,'All Cards'!$C$2:$C$190,">=0",'All Cards'!$C$2:$C$190,"<5") -> 64.29
A24: $5 – $25 | B24: =COUNTIFS('All Cards'!$C$2:$C$190,">=5",'All Cards'!$C$2:$C$190,"<25") -> 109 | C24: =SUMIFS('All Cards'!$C$2:$C$190,'All Cards'!$C$2:$C$190,">=5",'All Cards'!$C$2:$C$190,"<25") -> 1463.2
A25: $25 – $100 | B25: =COUNTIFS('All Cards'!$C$2:$C$190,">=25",'All Cards'!$C$2:$C$190,"<100") -> 39 | C25: =SUMIFS('All Cards'!$C$2:$C$190,'All Cards'!$C$2:$C$190,">=25",'All Cards'!$C$2:$C$190,"<100") -> 1887.14
A26: $100 – $500 | B26: =COUNTIFS('All Cards'!$C$2:$C$190,">=100",'All Cards'!$C$2:$C$190,"<500") -> 19 | C26: =SUMIFS('All Cards'!$C$2:$C$190,'All Cards'!$C$2:$C$190,">=100",'All Cards'!$C$2:$C$190,"<500") -> 4071.78
A27: $500+ | B27: =COUNTIFS('All Cards'!$C$2:$C$190,">=500",'All Cards'!$C$2:$C$190,"<9999999") -> 1 | C27: =SUMIFS('All Cards'!$C$2:$C$190,'All Cards'!$C$2:$C$190,">=500",'All Cards'!$C$2:$C$190,"<9999999") -> 605
A29: TOP 10 MOST VALUABLE (snapshot ranking — values update live)
A30: Card Name | B30: USD | C30: Confidence
A31: 2024-25 O-Pee-Chee Platinum - [Base] - Arctic Freeze #263 - Marquee Rookies - Macklin Celebrini #1/99 | B31: ='All Cards'!C162 -> 5.64 | C31: Low
A32: 2023-24 O-Pee-Chee Platinum - [Base] - Violet Pixels #201 - Marquee Rookies - Connor Bedard [PSA 10 GEM MT] #260/299 | B32: ='All Cards'!C135 -> 10 | C32: Low
A33: 2024-25 Upper Deck Series 2 - [Base] #451 - Young Guns - Macklin Celebrini [PSA 8 NM‑MT] | B33: ='All Cards'!C186 -> 2.11 | C33: High
A34: 2024-25 O-Pee-Chee Platinum - [Base] - Red Prism #263 - Marquee Rookies - Macklin Celebrini #2/199 | B34: ='All Cards'!C164 -> 5.34 | C34: High
A35: 2024-25 SPx - Excellence Redefined - Red #EX-9 - Connor Bedard, Nathan MacKinnon #9/10 | B35: ='All Cards'!C143 -> 8.04 | C35: Estimated
A36: 2023-24 Upper Deck Allure - Color Flow - Orange Yellow Spectrum #CF-16 - Connor Bedard [PSA 10 GEM MT] #125/199 | B36: ='All Cards'!C119 -> 13.19 | C36: Manual
A37: 2023-24 Upper Deck Series 2 - [Base] #451 - Young Guns - Connor Bedard [PSA 9 MINT] | B37: ='All Cards'!C32 -> 59.49 | C37: High
A38: 2023-24 O-Pee-Chee Platinum - [Base] - Red Prism #201 - Marquee Rookies - Connor Bedard [PSA 9 MINT] #70/199 | B38: ='All Cards'!C110 -> 14.61 | C38: Low
A39: 2023-24 O-Pee-Chee Platinum - [Base] - Pond Hockey Variants #202 - Marquee Rookies - Logan Cooley [PSA 10 GEM MT] | B39: ='All Cards'!C136 -> 10 | C39: Low
A40: 2023-24 O-Pee-Chee Platinum - [Base] - Emerald Surge #53 - Nick Suzuki [PSA 10 GEM MT] #10/10 | B40: ='All Cards'!C138 -> 9.64 | C40: Manual
A42: CONFIDENCE LEGEND
A43: High | B43: Direct eBay comp — full query matched variant + serial + set
A44: Medium | B44: Set-level comp — dropped parallel/variant name
A45: Low | B45: Broad fallback — player + card# + year only
A46: Estimated | B46: Nearby print-run comp adjusted by serial multiplier
...

Sheet By Player
A1: VALUE BY PLAYER (totals update when you edit All Cards)
A2: Edit Fair Value on 'All Cards' sheet (yellow column) — totals here update automatically
A3: Player | B3: # Cards | C3: Total USD
A4: Connor Bedard | B4: =COUNTIF('All Cards'!$J$2:$J$190,A4) -> 10 | C4: =SUMIF('All Cards'!$J$2:$J$190,A4,'All Cards'!$C$2:$C$190) -> 1763.87
A5: Macklin Celebrini | B5: =COUNTIF('All Cards'!$J$2:$J$190,A5) -> 8 | C5: =SUMIF('All Cards'!$J$2:$J$190,A5,'All Cards'!$C$2:$C$190) -> 1645.41
A6: Matthew Knies | B6: =COUNTIF('All Cards'!$J$2:$J$190,A6) -> 5 | C6: =SUMIF('All Cards'!$J$2:$J$190,A6,'All Cards'!$C$2:$C$190) -> 234.48
A7: Leo Carlsson | B7: =COUNTIF('All Cards'!$J$2:$J$190,A7) -> 3 | C7: =SUMIF('All Cards'!$J$2:$J$190,A7,'All Cards'!$C$2:$C$190) -> 267.41
A8: Marie-Philip Poulin | B8: =COUNTIF('All Cards'!$J$2:$J$190,A8) -> 4 | C8: =SUMIF('All Cards'!$J$2:$J$190,A8,'All Cards'!$C$2:$C$190) -> 263.47
A9: Adam Fantilli | B9: =COUNTIF('All Cards'!$J$2:$J$190,A9) -> 2 | C9: =SUMIF('All Cards'!$J$2:$J$190,A9,'All Cards'!$C$2:$C$190) -> 248.26
A10: Nick Suzuki | B10: =COUNTIF('All Cards'!$J$2:$J$190,A10) -> 2 | C10: =SUMIF('All Cards'!$J$2:$J$190,A10,'All Cards'!$C$2:$C$190) -> 210.14
A11: Logan Cooley | B11: =COUNTIF('All Cards'!$J$2:$J$190,A11) -> 1 | C11: =SUMIF('All Cards'!$J$2:$J$190,A11,'All Cards'!$C$2:$C$190) -> 150
A12: Artyom Levshunov | B12: =COUNTIF('All Cards'!$J$2:$J$190,A12) -> 2 | C12: =SUMIF('All Cards'!$J$2:$J$190,A12,'All Cards'!$C$2:$C$190) -> 208.06
A13: Zayne Parekh | B13: =COUNTIF('All Cards'!$J$2:$J$190,A13) -> 1 | C13: =SUMIF('All Cards'!$J$2:$J$190,A13,'All Cards'!$C$2:$C$190) -> 196.18
A14: Cutter Gauthier | B14: =COUNTIF('All Cards'!$J$2:$J$190,A14) -> 2 | C14: =SUMIF('All Cards'!$J$2:$J$190,A14,'All Cards'!$C$2:$C$190) -> 144.89
A15: Elias Pettersson | B15: =COUNTIF('All Cards'!$J$2:$J$190,A15) -> 1 | C15: =SUMIF('All Cards'!$J$2:$J$190,A15,'All Cards'!$C$2:$C$190) -> 9
... A131: Samantha Cogan | B131: =COUNTIF('All Cards'!$J$2:$J$190,A131) -> 1 | C131: =SUMIF('All Cards'!$J$2:$J$190,A131,'All Cards'!$C$2:$C$190) -> 0.45
A132: GRAND TOTAL | C132: =SUM('All Cards'!$C$2:$C$190) -> 8091.41

Sheet By Set
A1: VALUE BY SET (totals update when you edit All Cards)
A2: Edit Fair Value on 'All Cards' sheet (yellow column) — totals here update automatically
A3: Set Name | B3: # Cards | C3: Total USD
A4: 2023-24 O-Pee-Chee Platinum | B4: =COUNTIF('All Cards'!$K$2:$K$190,A4) -> 19 | C4: =SUMIF('All Cards'!$K$2:$K$190,A4,'All Cards'!$C$2:$C$190) -> 1874.28
A5: 2024-25 O-Pee-Chee Platinum | B5: =COUNTIF('All Cards'!$K$2:$K$190,A5) -> 12 | C5: =SUMIF('All Cards'!$K$2:$K$190,A5,'All Cards'!$C$2:$C$190) -> 1109.92
A6: 2024-25 Upper Deck Series 2 | B6: =COUNTIF('All Cards'!$K$2:$K$190,A6) -> 27 | C6: =SUMIF('All Cards'!$K$2:$K$190,A6,'All Cards'!$C$2:$C$190) -> 1021.77
A7: 2024 Upper Deck PWHL 1st Edition | B7: =COUNTIF('All Cards'!$K$2:$K$190,A7) -> 25 | C7: =SUMIF('All Cards'!$K$2:$K$190,A7,'All Cards'!$C$2:$C$190) -> 776.87
A8: 2024-25 SPx | B8: =COUNTIF('All Cards'!$K$2:$K$190,A8) -> 7 | C8: =SUMIF('All Cards'!$K$2:$K$190,A8,'All Cards'!$C$2:$C$190) -> 598.4
A9: 2025-26 Upper Deck Series 1 | B9: =COUNTIF('All Cards'!$K$2:$K$190,A9) -> 9 | C9: =SUMIF('All Cards'!$K$2:$K$190,A9,'All Cards'!$C$2:$C$190) -> 525.21
A10: 2023-24 Upper Deck Allure | B10: =COUNTIF('All Cards'!$K$2:$K$190,A10) -> 3 | C10: =SUMIF('All Cards'!$K$2:$K$190,A10,'All Cards'!$C$2:$C$190) -> 416.12
A11: 2023-24 Upper Deck Series 2 | B11: =COUNTIF('All Cards'!$K$2:$K$190,A11) -> 4 | C11: =SUMIF('All Cards'!$K$2:$K$190,A11,'All Cards'!$C$2:$C$190) -> 292.07
A12: 2023-24 SPx | B12: =COUNTIF('All Cards'!$K$2:$K$190,A12) -> 3 | C12: =SUMIF('All Cards'!$K$2:$K$190,A12,'All Cards'!$C$2:$C$190) -> 120
A13: 2023-24 Upper Deck Series 1 | B13: =COUNTIF('All Cards'!$K$2:$K$190,A13) -> 9 | C13: =SUMIF('All Cards'!$K$2:$K$190,A13,'All Cards'!$C$2:$C$190) -> 136.45
A14: 2018-19 Upper Deck Parkhurst | B14: =COUNTIF('All Cards'!$K$2:$K$190,A14) -> 1 | C14: =SUMIF('All Cards'!$K$2:$K$190,A14,'All Cards'!$C$2:$C$190) -> 9
A15: 2024-25 Skybox Metal Universe | B15: =COUNTIF('All Cards'!$K$2:$K$190,A15) -> 3 | C15: =SUMIF('All Cards'!$K$2:$K$190,A15,'All Cards'!$C$2:$C$190) -> 140.54
... A47: 2021-22 O-Pee-Chee Platinum | B47: =COUNTIF('All Cards'!$K$2:$K$190,A47) -> 1 | C47: =SUMIF('All Cards'!$K$2:$K$190,A47,'All Cards'!$C$2:$C$190) -> 4.48
A48: GRAND TOTAL | C48: =SUM('All Cards'!$C$2:$C$190) -> 8091.41

Sheet Charts
A1: VISUAL ANALYSIS (charts update when Fair Value is edited)
A3: Confidence | B3: Value USD | O3: Tier | P3: # Cards
A4: High | B4: =SUMIF('All Cards'!$D$2:$D$190,"high",'All Cards'!$C$2:$C$190) -> 3487.01 | O4: $0 – $5 | P4: =COUNTIFS('All Cards'!$C$2:$C$190,">=0",'All Cards'!$C$2:$C$190,"<5") -> 21
A5: Medium | B5: =SUMIF('All Cards'!$D$2:$D$190,"medium",'All Cards'!$C$2:$C$190) -> 177.8 | O5: $5 – $25 | P5: =COUNTIFS('All Cards'!$C$2:$C$190,">=5",'All Cards'!$C$2:$C$190,"<25") -> 109
A6: Low | B6: =SUMIF('All Cards'!$D$2:$D$190,"low",'All Cards'!$C$2:$C$190) -> 2917.06 | O6: $25 – $100 | P6: =COUNTIFS('All Cards'!$C$2:$C$190,">=25",'All Cards'!$C$2:$C$190,"<100") -> 39
A7: Estimated | B7: =SUMIF('All Cards'!$D$2:$D$190,"estimated",'All Cards'!$C$2:$C$190) -> 339.54 | O7: $100 – $500 | P7: =COUNTIFS('All Cards'!$C$2:$C$190,">=100",'All Cards'!$C$2:$C$190,"<500") -> 19
A8: Manual | B8: =SUMIF('All Cards'!$D$2:$D$190,"manual",'All Cards'!$C$2:$C$190) -> 1170 | O8: $500+ | P8: =COUNTIFS('All Cards'!$C$2:$C$190,">=500",'All Cards'!$C$2:$C$190,"<9999999") -> 1
A20: Player / Card | B20: USD | O20: Set | P20: USD
A21: Macklin Celebrini | B21: ='All Cards'!C162 -> 5.64 | O21: O-Pee-Chee Platinum | P21: =SUMIF('All Cards'!$K$2:$K$190,Q21,'All Cards'!$C$2:$C$190) -> 1874.28 | Q21: 2023-24 O-Pee-Chee Platinum
A22: Connor Bedard | B22: ='All Cards'!C135 -> 10 | O22: O-Pee-Chee Platinum | P22: =SUMIF('All Cards'!$K$2:$K$190,Q22,'All Cards'!$C$2:$C$190) -> 1109.92 | Q22: 2024-25 O-Pee-Chee Platinum
A23: Macklin Celebrini | B23: ='All Cards'!C186 -> 2.11 | O23: Upper Deck Series 2 | P23: =SUMIF('All Cards'!$K$2:$K$190,Q23,'All Cards'!$C$2:$C$190) -> 1021.77 | Q23: 2024-25 Upper Deck Series 2
A24: Macklin Celebrini | B24: ='All Cards'!C164 -> 5.34 | O24: Upper Deck PWHL 1st Edition | P24: =SUMIF('All Cards'!$K$2:$K$190,Q24,'All Cards'!$C$2:$C$190) -> 776.87 | Q24: 2024 Upper Deck PWHL 1st Edition
A25: Connor Bedard | B25: ='All Cards'!C143 -> 8.04 | O25: SPx | P25: =SUMIF('All Cards'!$K$2:$K$190,Q25,'All Cards'!$C$2:$C$190) -> 598.4 | Q25: 2024-25 SPx
A26: Connor Bedard | B26: ='All Cards'!C119 -> 13.19 | O26: Upper Deck Series 1 | P26: =SUMIF('All Cards'!$K$2:$K$190,Q26,'All Cards'!$C$2:$C$190) -> 525.21 | Q26: 2025-26 Upper Deck Series 1
A27: Connor Bedard | B27: ='All Cards'!C32 -> 59.49 | O27: Upper Deck Allure | P27: =SUMIF('All Cards'!$K$2:$K$190,Q27,'All Cards'!$C$2:$C$190) -> 416.12 | Q27: 2023-24 Upper Deck Allure
A28: Connor Bedard | B28: ='All Cards'!C110 -> 14.61 | O28: Upper Deck Series 2 | P28: =SUMIF('All Cards'!$K$2:$K$190,Q28,'All Cards'!$C$2:$C$190) -> 292.07 | Q28: 2023-24 Upper Deck Series 2
A29: Logan Cooley | B29: ='All Cards'!C136 -> 10 | O29: SPx | P29: =SUMIF('All Cards'!$K$2:$K$190,Q29,'All Cards'!$C$2:$C$190) -> 120 | Q29: 2023-24 SPx
A30: Nick Suzuki | B30: ='All Cards'!C138 -> 9.64 | O30: Upper Deck Series 1 | P30: =SUMIF('All Cards'!$K$2:$K$190,Q30,'All Cards'!$C$2:$C$190) -> 136.45 | Q30: 2023-24 Upper Deck Series 1

Sheet Value Tiers
A1: $0 – $5
A2: Live Count: | B2: =COUNTIFS('All Cards'!$C$2:$C$190,">=0",'All Cards'!$C$2:$C$190,"<5") -> 21 | C2: =SUMIFS('All Cards'!$C$2:$C$190,'All Cards'!$C$2:$C$190,">=0",'All Cards'!$C$2:$C$190,"<5") -> 64.29
A3: Card Name | B3: Fair Value (USD) | C3: Confidence
A4: 2023-24 Upper Deck Series 1 - [Base] #201 - Young Guns - Matthew Coronato | B4: ='All Cards'!C8 -> 273.77 | C4: high
A5: 2024-25 Upper Deck Fleer Ultra - [Base] - Blue Foil #64 - Leo Carlsson #65/399 | B5: ='All Cards'!C131 -> 10.57 | C5: low
A6: 2021-22 O-Pee-Chee Platinum - [Base] - Rainbow Color Wheel #284 - Marquee Rookies - Seth Jarvis | B6: ='All Cards'!C90 -> 17.44 | C6: low
A7: 2024-25 Upper Deck Series 1 - [Base] #244 - Young Guns - Logan Stankoven | B7: ='All Cards'!C177 -> 3.99 | C7: high
A8: 2024-25 Upper Deck Series 2 - [Base] #474 - Young Guns - Rutger McGroarty | B8: ='All Cards'!C48 -> 39.03 | C8: high
A9: 2025 Upper Deck DC x NHL Crossover - [Base] - Gold #4 - Superman™ & Krypto™ | B9: ='All Cards'!C126 -> 11.67 | C9: high
A10: 2024-25 Upper Deck Series 2 - [Base] #478 - Young Guns - Conor Geekie | B10: ='All Cards'!C49 -> 38.7 | C10: high
A11: 2024-25 Upper Deck Series 2 - [Base] - Outburst #463 - Young Guns - Maxim Tsyplakov | B11: ='All Cards'!C35 -> 55.88 | C11: high
A12: 2023-24 Upper Deck Parkhurst - Prominent Prospects - Blue #PP-MA - Matthew Kessel [Passed Pre‑Grade Review] #24/25 | B12: ='All Cards'!C106 -> 15.06 | C12: manual
A13: 2024-25 Upper Deck Series 2 - UD Canvas - Black & White #C257 - Program of Excellence - Joshua Roy | B13: ='All Cards'!C76 -> 19.84 | C13: high
A14: 2020-21 O-Pee-Chee Platinum - Retro #R-59 - Rookies - Brandon Hagel | B14: ='All Cards'!C6 -> 313.3 | C14: high
A15: 2025 Upper Deck Team Canada Juniors - [Base] - Outburst #42 - Alex Huang | B15: ='All Cards'!C145 -> 7.99 | C15: low
A16: 2024-25 Upper Deck Series 2 - [Base] #497 - Young Guns - Logan Mailloux, Lane Hutson | B16: ='All Cards'!C50 -> 37.28 | C16: high
A17: 2023-24 O-Pee-Chee Platinum - [Base] - Violet Pixels #236 - Marquee Rookies - Connor Zary [Passed Pre‑Grade Review] #168/299 | B17: ='All Cards'!C81 -> 19.26 | C17: low
A18: 2024-25 O-Pee-Chee Platinum - [Base] - Violet Pixels #273 - Marquee Rookies - Ivan Ivan #292/299 | B18: ='All Cards'!C159 -> 6.11 | C18: high
A19: 2023-24 Upper Deck Series 2 - [Base] #492 - Young Guns - Dmitri Voronkov | B19: ='All Cards'!C19 -> 124.13 | C19: high
A20: 2023-24 O-Pee-Chee Platinum - [Base] - Cosmic #256 - Marquee Rookies - John Beecher #58/65 | B20: ='All Cards'!C58 -> 28.98 | C20: manual
A21: 2024 Upper Deck PWHL 1st Edition - [Base] - Exclusives #3 - Elaine Chuli #68/100 | B21: ='All Cards'!C84 -> 18.52 | C21: estimated
A22: 2024 Upper Deck PWHL 1st Edition - [Base] - Exclusives #31 - Samantha Cogan #43/100 | B22: ='All Cards'!C85 -> 18.21 | C22: estimated
A24: $5 – $25
A25: Live Count: | B25: =COUNTIFS('All Cards'!$C$2:$C$190,">=5",'All Cards'!$C$2:$C$190,"<25") -> 109 | C25: =SUMIFS('All Cards'!$C$2:$C$190,'All Cards'!$C$2:$C$190,">=5",'All Cards'!$C$2:$C$190,"<25") -> 1463.2
A26: Card Name | B26: Fair Value (USD) | C26: Confidence
A27: 2024-25 Upper Deck UD Rookie Debut - [Base] #9 - Lane Hutson | B27: ='All Cards'!C26 -> 3 | C27: high
A28: 2024 Upper Deck PWHL 1st Edition - [Base] - Outburst #56 - Young Guns - Alina Muller | B28: ='All Cards'!C99 -> 16.18 | C28: high
A29: 2024-25 Upper Deck Credentials - [Base] - Autographs #145 - Debut Ticket Access - Collin Graf #163/199 | B29: ='All Cards'!C130 -> 10.6 | C29: low
A30: 2024-25 Upper Deck Series 2 - UD Canvas #C215 - Young Guns - Jackson Blake | B30: ='All Cards'!C43 -> 50 | C30: high
A31: 2019-20 Upper Deck Parkhurst - [Base] #320 - Rookies - Jack Hughes | B31: ='All Cards'!C4 -> 368 | C31: high
A32: 2022-23 Skybox Metal Universe - Hardware #HW-4 - Nazem Kadri | B32: ='All Cards'!C18 -> 124.13 | C32: high
A33: 2024-25 Skybox Metal Universe - [Base] - Autographs #121 - Rookies - Rutger McGroarty | B33: ='All Cards'!C103 -> 15.98 | C33: high
A34: 2024-25 Upper Deck Fleer Ultra - [Base] - Silver Foil #204 - Rookies - Lane Hutson | B34: ='All Cards'!C124 -> 12.25 | C34: high
A35: 2025-26 Upper Deck Series 1 - [Base] #226 - Young Guns - Dalibor Dvorsky | B35: ='All Cards'!C171 -> 4.91 | C35: high
A36: 2024-25 O-Pee-Chee Platinum - O-Pee-Chee Premier #OP8 - Connor Bedard | B36: ='All Cards'!C154 -> 6.57 | C36: low
A37: 2024-25 Upper Deck Game Dated Moments - Rookie of the Month #R-1 - October - Matvei Michkov | B37: ='All Cards'!C33 -> 58 | C37: low
A38: 2024 Upper Deck PWHL 1st Edition - UD Portraits #P-2 - Marie-Philip Poulin | B38: ='All Cards'!C67 -> 22.48 | C38: high
A39: 2025 Upper Deck Team Canada Juniors - Team Canada FX #FX-24 - Chloe Primerano | B39: ='All Cards'!C148 -> 7.28 | C39: high
A40: 2024-25 Upper Deck PWHL - [Base] - Outburst #52 - Young Guns - Noora Tulus | B40: ='All Cards'!C142 -> 8.31 | C40: high
A41: 2025-26 Upper Deck Series 1 - [Base] #201 - Young Guns - Artyom Levshunov | B41: ='All Cards'!C168 -> 5 | C41: high
...

Sheet Under $5
A1: CARDS UNDER $5 (snapshot list — values link to All Cards)
A2: Prices link to 'All Cards' sheet. If a price changes above $5, use the All Cards filter for a live view.
A3: Live count of cards under $5: | B3: =COUNTIFS('All Cards'!$C$2:$C$190,">=0.01",'All Cards'!$C$2:$C$190,"<5") -> 21
A4: Card Name | B4: Fair Value (USD) | C4: Confidence | D4: # Sales
A5: 2024 Upper Deck PWHL 1st Edition - [Base] - Exclusives #3 - Elaine Chuli #68/100 | B5: ='All Cards'!C84 -> 18.52 | C5: estimated | D5: 1
A6: 2024 Upper Deck PWHL 1st Edition - [Base] - Exclusives #31 - Samantha Cogan #43/100 | B6: ='All Cards'!C85 -> 18.21 | C6: estimated | D6: 1
A7: 2023-24 Upper Deck Series 2 - [Base] #492 - Young Guns - Dmitri Voronkov | B7: ='All Cards'!C19 -> 124.13 | C7: high | D7: 22
A8: 2023-24 O-Pee-Chee Platinum - [Base] - Cosmic #256 - Marquee Rookies - John Beecher #58/65 | B8: ='All Cards'!C58 -> 28.98 | C8: manual | D8: —
A9: 2024-25 O-Pee-Chee Platinum - [Base] - Violet Pixels #273 - Marquee Rookies - Ivan Ivan #292/299 | B9: ='All Cards'!C159 -> 6.11 | C9: high | D9: 1
A10: 2023-24 O-Pee-Chee Platinum - [Base] - Violet Pixels #236 - Marquee Rookies - Connor Zary [Passed Pre‑Grade Review] #168/299 | B10: ='All Cards'!C81 -> 19.26 | C10: low | D10: 2
A11: 2024-25 Upper Deck Series 2 - [Base] #497 - Young Guns - Logan Mailloux, Lane Hutson | B11: ='All Cards'!C50 -> 37.28 | C11: high | D11: 16
A12: 2025 Upper Deck Team Canada Juniors - [Base] - Outburst #42 - Alex Huang | B12: ='All Cards'!C145 -> 7.99 | C12: low | D12: 6
A13: 2020-21 O-Pee-Chee Platinum - Retro #R-59 - Rookies - Brandon Hagel | B13: ='All Cards'!C6 -> 313.3 | C13: high | D13: 1
A14: 2024-25 Upper Deck Series 2 - UD Canvas - Black & White #C257 - Program of Excellence - Joshua Roy | B14: ='All Cards'!C76 -> 19.84 | C14: high | D14: 4
A15: 2024-25 Upper Deck Series 2 - [Base] - Outburst #463 - Young Guns - Maxim Tsyplakov | B15: ='All Cards'!C35 -> 55.88 | C15: high | D15: 4
A16: 2023-24 Upper Deck Parkhurst - Prominent Prospects - Blue #PP-MA - Matthew Kessel [Passed Pre‑Grade Review] #24/25 | B16: ='All Cards'!C106 -> 15.06 | C16: manual | D16: 0
A17: 2024-25 Upper Deck Series 2 - [Base] #478 - Young Guns - Conor Geekie | B17: ='All Cards'!C49 -> 38.7 | C17: high | D17: 77
A18: 2025 Upper Deck DC x NHL Crossover - [Base] - Gold #4 - Superman™ & Krypto™ | B18: ='All Cards'!C126 -> 11.67 | C18: high | D18: 2
A19: 2024-25 Upper Deck Series 2 - [Base] #474 - Young Guns - Rutger McGroarty | B19: ='All Cards'!C48 -> 39.03 | C19: high | D19: 91
A20: 2024-25 Upper Deck Series 1 - [Base] #244 - Young Guns - Logan Stankoven | B20: ='All Cards'!C177 -> 3.99 | C20: high | D20: 82
A21: 2021-22 O-Pee-Chee Platinum - [Base] - Rainbow Color Wheel #284 - Marquee Rookies - Seth Jarvis | B21: ='All Cards'!C90 -> 17.44 | C21: low | D21: 19
A22: 2024-25 Upper Deck Fleer Ultra - [Base] - Blue Foil #64 - Leo Carlsson #65/399 | B22: ='All Cards'!C131 -> 10.57 | C22: low | D22: 2
A23: 2023-24 Upper Deck Series 1 - [Base] #201 - Young Guns - Matthew Coronato | B23: ='All Cards'!C8 -> 273.77 | C23: high | D23: 23

Sheet Manual Entries
A1: MANUALLY PRICED CARDS (18 cards) — prices link to All Cards
A2: Card Name | B2: Manual Price (USD) | C2: Notes
A3: 2023-24 Upper Deck Series 1 - [Base] - Deluxe #144 - Tomas Hertl #1/250 | B3: ='All Cards'!C14 -> 187.91 | C3: No eBay sold listings — comp price entered manually
A4: 2024 Upper Deck - UD Retro Rookies #RR-10 - Corey Conners | B4: ='All Cards'!C22 -> 100.15 | C4: No eBay sold listings — comp price entered manually
A5: 2023-24 O-Pee-Chee Platinum - [Base] - Cosmic #256 - Marquee Rookies - John Beecher #58/65 | B5: ='All Cards'!C58 -> 28.98 | C5: No eBay sold listings — comp price entered manually
A6: 2023-24 SPx - Signature Fabrics - Spectrum Patch #SF-JT - John Tavares #2/5 | B6: ='All Cards'!C74 -> 20.2 | C6: No eBay sold listings — comp price entered manually
A7: 2024-25 4 Nations Face-Off - Game Dated Moments #2 - (Feb. 12, 2025) - Crosby Dishes out Three Assists as Canada Tops Sweden at the 4 Nations Face-Off™ | B7: ='All Cards'!C77 -> 19.73 | C7: No eBay sold listings — comp price entered manually
A8: 2024-25 4 Nations Face-Off - Game Dated Moments - Silver #2 - (Feb. 12, 2025) - Crosby Dishes out Three Assists as Canada Tops Sweden at the 4 Nations Face-Off™ | B8: ='All Cards'!C78 -> 19.47 | C8: No eBay sold listings — comp price entered manually
A9: 2023-24 Upper Deck Parkhurst - Prominent Prospects - Blue #PP-MA - Matthew Kessel [Passed Pre‑Grade Review] #24/25 | B9: ='All Cards'!C106 -> 15.06 | C9: No eBay sold listings — comp price entered manually
A10: 2023-24 Upper Deck Parkhurst - Prominent Prospects - Purple #PP-BF - Brock Faber [Passed Pre‑Grade Review] #15/99 | B10: ='All Cards'!C107 -> 15 | C10: No eBay sold listings — comp price entered manually
A11: 2023-24 Upper Deck Allure - Color Flow - Orange Yellow Spectrum #CF-16 - Connor Bedard [PSA 10 GEM MT] #125/199 | B11: ='All Cards'!C119 -> 13.19 | C11: No eBay sold listings — comp price entered manually
A12: 2023-24 O-Pee-Chee Platinum - [Base] - Emerald Surge #53 - Nick Suzuki [PSA 10 GEM MT] #10/10 | B12: ='All Cards'!C138 -> 9.64 | C12: No eBay sold listings — comp price entered manually
A13: 1998-99 In the Game Be A Player - [Base] - Gold 20th National Atlanta #284 - Curtis Joseph #8/10 | B13: ='All Cards'!C140 -> 8.74 | C13: No eBay sold listings — comp price entered manually
A14: 2025 Upper Deck Team Canada Juniors - License to Ice #LI-23 - Chloe Primerano | B14: ='All Cards'!C150 -> 7.06 | C14: No eBay sold listings — comp price entered manually
A15: 2023-24 O-Pee-Chee Platinum - Photo Driven - Red Pixel #PD-6 - Auston Matthews [PSA 10 GEM MT] #75/85 | B15: ='All Cards'!C179 -> 3 | C15: No eBay sold listings — comp price entered manually
A16: 2023-24 SPx - [Base] - Purple Parallax #134 - Rookies - Matthew Knies [PSA 9 MINT] #85/149 | B16: ='All Cards'!C180 -> 3 | C16: No eBay sold listings — comp price entered manually
A17: 2024-25 Upper Deck Series 2 - Young Guns Renewed #201.3 - Connor McDavid [PSA 9 MINT] | B17: ='All Cards'!C184 -> 2.69 | C17: No eBay sold listings — comp price entered manually
A18: 2024-25 Upper Deck Series 2 - UD Canvas #C161 - Joseph Woll [PSA 10 GEM MT] | B18: ='All Cards'!C185 -> 2.37 | C18: No eBay sold listings — comp price entered manually
A19: 2021 Bowman Chrome - [Base] - Blue Refractor #49 - Alejandro Kirk [PSA 9 MINT] #113/150 | B19: ='All Cards'!C187 -> 2 | C19: No eBay sold listings — comp price entered manually
A20: 2024-25 SPx - [Base] #166 - Rookie Holograms - Macklin Celebrini [PSA 8 NM‑MT] | B20: ='All Cards'!C190 -> 0.45 | C20: No eBay sold listings — comp price entered manually
A21: SUBTOTAL | B21: =SUMIF('All Cards'!$D$2:$D$190,"manual",'All Cards'!$C$2:$C$190) -> 1170
